{"errorMessage": "An error occurred (AccessDenied) when calling the ListObjectsV2 operation: Access Denied", "errorType": "ClientError", "stackTrace": ["  File \"/var/task/lambda_function.py\", line 16, in lambda_handler\n    approved_objects = s3.list_objects_v2(Bucket=approved_bucket, Prefix=approved_prefix)['Contents']\n", "  File \"/var/runtime/botocore/client.py\", line 530, in _api_call\n    return self._make_api_call(operation_name, kwargs)\n", "  File \"/var/runtime/botocore/client.py\", line 960, in _make_api_call\n    raise error_class(parsed_response, operation_name)\n"]}